<?xml version="1.0" ?>
<robot name="m2wr" xmlns:xacro="https://www.ros.org/wiki/xacro" >   <!-- this second parameter is importent to make this file a valid xacro file -->

<!-- in rviz red - x  | green - y | blue -z  -->

<!-- while using odom tf do not forget to do   rosparam set use_sim_time true  as this gives all simulations the same time -->


<xacro:include filename="$(find carmodel_description)/urdf/material.xacro" />
<xacro:include filename="$(find carmodel_description)/urdf/gazebo.xacro" />
<xacro:include filename="$(find carmodel_description)/urdf/link_joint.xacro" />
<xacro:include filename="$(find carmodel_description)/urdf/mecanum_wheel_macro.xacro" />

<xacro:include filename="$(find carmodel_description)/urdf/_t265.urdf.xacro"/>
  <xacro:sensor_t265  parent="base_link" name="T265_camera" topics_ns="T265_camera"
                      odom_xyz="0.0 0.0 0.25" odom_rpy="0.0 0.0 0.0">
    <origin xyz="0.0 0.0 0.25" rpy="0.0 0.0 0.0"/>
  </xacro:sensor_t265>
    
  <link name="base_link">
    <!-- pose and inertial -->
    <pose>0 0 0.1 0 0 0</pose>
    
    <inertial>
      <mass value="5"/>
      <origin rpy="0 0 0" xyz="0 0 0.1"/>
      <inertia ixx="0.0395416666667" ixy="0" ixz="0" iyy="0.106208333333" iyz="0" izz="0.106208333333"/>
    </inertial>
    
    <collision name="collision_chassis">
      <geometry>
        <box size="0.5 0.3 0.07"/>
      </geometry>
    </collision>
    
    <visual>
      <origin rpy="0 0 0" xyz="0 0 0"/>
      <geometry>
        <box size="0.5 0.3 0.07"/>
      </geometry>
      <material name="blue"/>
    </visual>
  </link>


  <!-- Create sensor link  -->
  <xacro:sensor_link /> 
  <!-- Create sensor joint --> 
  <xacro:sensor_joint /> 
  <xacro:mecanum_wheel name="front_right" side="1"  interface="hardware_interface/EffortJointInterface"/>
  <xacro:mecanum_wheel name="front_left"  side="-1" interface="hardware_interface/EffortJointInterface"/>
  <xacro:mecanum_wheel name="rear_right"  side="-1" interface="hardware_interface/EffortJointInterface"/>
  <xacro:mecanum_wheel name="rear_left"   side="1"  interface="hardware_interface/EffortJointInterface"/>


  <joint name="front_right_wheel_joint" type="continuous">    
    <origin xyz="0.15 -0.19 0" rpy="0 0 ${pi/2}" />
    <axis xyz="1 0 0" />
    <parent link="base_link" />
    <child link="front_right_wheel_link" />    
  </joint>

  <joint name="front_left_wheel_joint" type="continuous">
    <origin xyz="0.15 0.19 0" rpy="0 0 ${pi/2}" />
    <axis xyz="1 0 0" />
    <parent link="base_link" />
    <child link="front_left_wheel_link" />
  </joint>

  <joint name="rear_right_wheel_joint" type="continuous">
    <origin xyz="-0.15 -0.19 0" rpy="0 0 ${pi/2}" />
    <axis xyz="1 0 0" />
    <parent link="base_link" />
    <child link="rear_right_wheel_link" />
  </joint>

  <joint name="rear_left_wheel_joint" type="continuous">
    <origin xyz="-0.15 0.19 0" rpy="0 0 ${pi/2}" />
    <axis xyz="1 0 0" />
    <parent link="base_link" />
    <child link="rear_left_wheel_link" />
  </joint>

  <!-- Create wheel right 
  <xacro:wheel_link name="link_right_wheel" />
   Create joint right 
  <xacro:joint_wheel name="joint_right_wheel" param_xyz="-0.15 0.15 0" child="link_right_wheel"  />
  Create wheel left 
  <xacro:wheel_link name="link_left_wheel" />
   Create joint left 
  <xacro:joint_wheel name="joint_left_wheel" param_xyz="-0.15 -0.15 0" child="link_left_wheel"  />
   front left
  <xacro:wheel_link name="link_front_left_wheel" />
  <xacro:joint_wheel name="joint_front_left_wheel" param_xyz="0.13 -0.15 0" child="link_front_left_wheel"  />
  front right
  <xacro:wheel_link
   name="link_front_right_wheel" />
  <xacro:joint_wheel name="joint_front_right_wheel" param_xyz="0.13 0.15 0" child="link_front_right_wheel"  /> -->
</robot>